['Traceback (most recent call last):\n', '  File "c:\\Users\\Parikh Agri Laptop\\OneDrive\\Code\\m.Stock Interface\\.venv\\Lib\\site-packages\\tradingapi_a\\mconnect.py", line 307, in get_ltp\n    get_ltp_data=self._get(\n        route="market_ltp",\n        url_args=None,\n        params=ltp_details\n    )\n', '  File "c:\\Users\\Parikh Agri Laptop\\OneDrive\\Code\\m.Stock Interface\\.venv\\Lib\\site-packages\\tradingapi_a\\mconnect.py", line 477, in _get\n    return self._request(route, "GET", url_args=url_args,content_type=content_type, params=params, is_json=is_json)\n           ~~~~~~~~~~~~~^^^^^^^^^^^^^^^^^^^^^^^^^^^^^^^^^^^^^^^^^^^^^^^^^^^^^^^^^^^^^^^^^^^^^^^^^^^^^^^^^^^^^^^^^^^\n', '  File "c:\\Users\\Parikh Agri Laptop\\OneDrive\\Code\\m.Stock Interface\\.venv\\Lib\\site-packages\\tradingapi_a\\mconnect.py", line 561, in _request\n    raise exp(data["message"], code=response_data.status_code)\n', 'tradingapi_a.exceptions.TokenException: Incorrect auth. Please try again.\n']
['Traceback (most recent call last):\n', '  File "c:\\Users\\Parikh Agri Laptop\\OneDrive\\Code\\m.Stock Interface\\.venv\\Lib\\site-packages\\tradingapi_a\\mconnect.py", line 307, in get_ltp\n    get_ltp_data=self._get(\n        route="market_ltp",\n        url_args=None,\n        params=ltp_details\n    )\n', '  File "c:\\Users\\Parikh Agri Laptop\\OneDrive\\Code\\m.Stock Interface\\.venv\\Lib\\site-packages\\tradingapi_a\\mconnect.py", line 477, in _get\n    return self._request(route, "GET", url_args=url_args,content_type=content_type, params=params, is_json=is_json)\n           ~~~~~~~~~~~~~^^^^^^^^^^^^^^^^^^^^^^^^^^^^^^^^^^^^^^^^^^^^^^^^^^^^^^^^^^^^^^^^^^^^^^^^^^^^^^^^^^^^^^^^^^^\n', '  File "c:\\Users\\Parikh Agri Laptop\\OneDrive\\Code\\m.Stock Interface\\.venv\\Lib\\site-packages\\tradingapi_a\\mconnect.py", line 561, in _request\n    raise exp(data["message"], code=response_data.status_code)\n', "tradingapi_a.exceptions.InputException: Invalid symbol. Scrip Name 'reliance' not found in exchange file.\n"]
['Traceback (most recent call last):\n', '  File "c:\\Users\\Parikh Agri Laptop\\OneDrive\\Code\\m.Stock Interface\\.venv\\Lib\\site-packages\\tradingapi_a\\mconnect.py", line 307, in get_ltp\n    get_ltp_data=self._get(\n        route="market_ltp",\n        url_args=None,\n        params=ltp_details\n    )\n', '  File "c:\\Users\\Parikh Agri Laptop\\OneDrive\\Code\\m.Stock Interface\\.venv\\Lib\\site-packages\\tradingapi_a\\mconnect.py", line 477, in _get\n    return self._request(route, "GET", url_args=url_args,content_type=content_type, params=params, is_json=is_json)\n           ~~~~~~~~~~~~~^^^^^^^^^^^^^^^^^^^^^^^^^^^^^^^^^^^^^^^^^^^^^^^^^^^^^^^^^^^^^^^^^^^^^^^^^^^^^^^^^^^^^^^^^^^\n', '  File "c:\\Users\\Parikh Agri Laptop\\OneDrive\\Code\\m.Stock Interface\\.venv\\Lib\\site-packages\\tradingapi_a\\mconnect.py", line 561, in _request\n    raise exp(data["message"], code=response_data.status_code)\n', 'tradingapi_a.exceptions.TokenException: Incorrect auth. Please try again.\n']
['Traceback (most recent call last):\n', '  File "c:\\Users\\Parikh Agri Laptop\\OneDrive\\Code\\m.Stock Interface\\.venv\\Lib\\site-packages\\tradingapi_a\\mconnect.py", line 307, in get_ltp\n    get_ltp_data=self._get(\n        route="market_ltp",\n        url_args=None,\n        params=ltp_details\n    )\n', '  File "c:\\Users\\Parikh Agri Laptop\\OneDrive\\Code\\m.Stock Interface\\.venv\\Lib\\site-packages\\tradingapi_a\\mconnect.py", line 477, in _get\n    return self._request(route, "GET", url_args=url_args,content_type=content_type, params=params, is_json=is_json)\n           ~~~~~~~~~~~~~^^^^^^^^^^^^^^^^^^^^^^^^^^^^^^^^^^^^^^^^^^^^^^^^^^^^^^^^^^^^^^^^^^^^^^^^^^^^^^^^^^^^^^^^^^^\n', '  File "c:\\Users\\Parikh Agri Laptop\\OneDrive\\Code\\m.Stock Interface\\.venv\\Lib\\site-packages\\tradingapi_a\\mconnect.py", line 561, in _request\n    raise exp(data["message"], code=response_data.status_code)\n', "tradingapi_a.exceptions.InputException: Invalid symbol. Scrip Name 'NIFTY28AUG2524600CE' not found in exchange file.\n"]
['Traceback (most recent call last):\n', '  File "c:\\Users\\Parikh Agri Laptop\\OneDrive\\Code\\m.Stock Interface\\.venv\\Lib\\site-packages\\urllib3\\connection.py", line 198, in _new_conn\n    sock = connection.create_connection(\n        (self._dns_host, self.port),\n    ...<2 lines>...\n        socket_options=self.socket_options,\n    )\n', '  File "c:\\Users\\Parikh Agri Laptop\\OneDrive\\Code\\m.Stock Interface\\.venv\\Lib\\site-packages\\urllib3\\util\\connection.py", line 60, in create_connection\n    for res in socket.getaddrinfo(host, port, family, socket.SOCK_STREAM):\n               ~~~~~~~~~~~~~~~~~~^^^^^^^^^^^^^^^^^^^^^^^^^^^^^^^^^^^^^^^^\n', '  File "C:\\Python313\\Lib\\socket.py", line 977, in getaddrinfo\n    for res in _socket.getaddrinfo(host, port, family, type, proto, flags):\n               ~~~~~~~~~~~~~~~~~~~^^^^^^^^^^^^^^^^^^^^^^^^^^^^^^^^^^^^^^^^\n', 'socket.gaierror: [Errno 11001] getaddrinfo failed\n', '\nThe above exception was the direct cause of the following exception:\n\n', 'Traceback (most recent call last):\n', '  File "c:\\Users\\Parikh Agri Laptop\\OneDrive\\Code\\m.Stock Interface\\.venv\\Lib\\site-packages\\urllib3\\connectionpool.py", line 787, in urlopen\n    response = self._make_request(\n        conn,\n    ...<10 lines>...\n        **response_kw,\n    )\n', '  File "c:\\Users\\Parikh Agri Laptop\\OneDrive\\Code\\m.Stock Interface\\.venv\\Lib\\site-packages\\urllib3\\connectionpool.py", line 488, in _make_request\n    raise new_e\n', '  File "c:\\Users\\Parikh Agri Laptop\\OneDrive\\Code\\m.Stock Interface\\.venv\\Lib\\site-packages\\urllib3\\connectionpool.py", line 464, in _make_request\n    self._validate_conn(conn)\n    ~~~~~~~~~~~~~~~~~~~^^^^^^\n', '  File "c:\\Users\\Parikh Agri Laptop\\OneDrive\\Code\\m.Stock Interface\\.venv\\Lib\\site-packages\\urllib3\\connectionpool.py", line 1093, in _validate_conn\n    conn.connect()\n    ~~~~~~~~~~~~^^\n', '  File "c:\\Users\\Parikh Agri Laptop\\OneDrive\\Code\\m.Stock Interface\\.venv\\Lib\\site-packages\\urllib3\\connection.py", line 753, in connect\n    self.sock = sock = self._new_conn()\n                       ~~~~~~~~~~~~~~^^\n', '  File "c:\\Users\\Parikh Agri Laptop\\OneDrive\\Code\\m.Stock Interface\\.venv\\Lib\\site-packages\\urllib3\\connection.py", line 205, in _new_conn\n    raise NameResolutionError(self.host, self, e) from e\n', "urllib3.exceptions.NameResolutionError: <urllib3.connection.HTTPSConnection object at 0x000002B9FDA738C0>: Failed to resolve 'api.mstock.trade' ([Errno 11001] getaddrinfo failed)\n", '\nThe above exception was the direct cause of the following exception:\n\n', 'Traceback (most recent call last):\n', '  File "c:\\Users\\Parikh Agri Laptop\\OneDrive\\Code\\m.Stock Interface\\.venv\\Lib\\site-packages\\requests\\adapters.py", line 644, in send\n    resp = conn.urlopen(\n        method=request.method,\n    ...<9 lines>...\n        chunked=chunked,\n    )\n', '  File "c:\\Users\\Parikh Agri Laptop\\OneDrive\\Code\\m.Stock Interface\\.venv\\Lib\\site-packages\\urllib3\\connectionpool.py", line 841, in urlopen\n    retries = retries.increment(\n        method, url, error=new_e, _pool=self, _stacktrace=sys.exc_info()[2]\n    )\n', '  File "c:\\Users\\Parikh Agri Laptop\\OneDrive\\Code\\m.Stock Interface\\.venv\\Lib\\site-packages\\urllib3\\util\\retry.py", line 519, in increment\n    raise MaxRetryError(_pool, url, reason) from reason  # type: ignore[arg-type]\n    ^^^^^^^^^^^^^^^^^^^^^^^^^^^^^^^^^^^^^^^^^^^^^^^^^^^\n', 'urllib3.exceptions.MaxRetryError: HTTPSConnectionPool(host=\'api.mstock.trade\', port=443): Max retries exceeded with url: /openapi/typea/instruments/quote/ltp?i=NSE%3ASBIN (Caused by NameResolutionError("<urllib3.connection.HTTPSConnection object at 0x000002B9FDA738C0>: Failed to resolve \'api.mstock.trade\' ([Errno 11001] getaddrinfo failed)"))\n', '\nDuring handling of the above exception, another exception occurred:\n\n', 'Traceback (most recent call last):\n', '  File "c:\\Users\\Parikh Agri Laptop\\OneDrive\\Code\\m.Stock Interface\\.venv\\Lib\\site-packages\\tradingapi_a\\mconnect.py", line 307, in get_ltp\n    get_ltp_data=self._get(\n        route="market_ltp",\n        url_args=None,\n        params=ltp_details\n    )\n', '  File "c:\\Users\\Parikh Agri Laptop\\OneDrive\\Code\\m.Stock Interface\\.venv\\Lib\\site-packages\\tradingapi_a\\mconnect.py", line 477, in _get\n    return self._request(route, "GET", url_args=url_args,content_type=content_type, params=params, is_json=is_json)\n           ~~~~~~~~~~~~~^^^^^^^^^^^^^^^^^^^^^^^^^^^^^^^^^^^^^^^^^^^^^^^^^^^^^^^^^^^^^^^^^^^^^^^^^^^^^^^^^^^^^^^^^^^\n', '  File "c:\\Users\\Parikh Agri Laptop\\OneDrive\\Code\\m.Stock Interface\\.venv\\Lib\\site-packages\\tradingapi_a\\mconnect.py", line 536, in _request\n    raise e\n', '  File "c:\\Users\\Parikh Agri Laptop\\OneDrive\\Code\\m.Stock Interface\\.venv\\Lib\\site-packages\\tradingapi_a\\mconnect.py", line 526, in _request\n    response_data = self.request_session.request(method,\n                                url,\n    ...<5 lines>...\n                                allow_redirects=True,\n                                timeout=self.timeout)\n', '  File "c:\\Users\\Parikh Agri Laptop\\OneDrive\\Code\\m.Stock Interface\\.venv\\Lib\\site-packages\\requests\\sessions.py", line 589, in request\n    resp = self.send(prep, **send_kwargs)\n', '  File "c:\\Users\\Parikh Agri Laptop\\OneDrive\\Code\\m.Stock Interface\\.venv\\Lib\\site-packages\\requests\\sessions.py", line 703, in send\n    r = adapter.send(request, **kwargs)\n', '  File "c:\\Users\\Parikh Agri Laptop\\OneDrive\\Code\\m.Stock Interface\\.venv\\Lib\\site-packages\\requests\\adapters.py", line 677, in send\n    raise ConnectionError(e, request=request)\n', 'requests.exceptions.ConnectionError: HTTPSConnectionPool(host=\'api.mstock.trade\', port=443): Max retries exceeded with url: /openapi/typea/instruments/quote/ltp?i=NSE%3ASBIN (Caused by NameResolutionError("<urllib3.connection.HTTPSConnection object at 0x000002B9FDA738C0>: Failed to resolve \'api.mstock.trade\' ([Errno 11001] getaddrinfo failed)"))\n']
['Traceback (most recent call last):\n', '  File "c:\\Users\\Parikh Agri Laptop\\OneDrive\\Code\\m.Stock Interface\\.venv\\Lib\\site-packages\\urllib3\\connection.py", line 198, in _new_conn\n    sock = connection.create_connection(\n        (self._dns_host, self.port),\n    ...<2 lines>...\n        socket_options=self.socket_options,\n    )\n', '  File "c:\\Users\\Parikh Agri Laptop\\OneDrive\\Code\\m.Stock Interface\\.venv\\Lib\\site-packages\\urllib3\\util\\connection.py", line 60, in create_connection\n    for res in socket.getaddrinfo(host, port, family, socket.SOCK_STREAM):\n               ~~~~~~~~~~~~~~~~~~^^^^^^^^^^^^^^^^^^^^^^^^^^^^^^^^^^^^^^^^\n', '  File "C:\\Python313\\Lib\\socket.py", line 977, in getaddrinfo\n    for res in _socket.getaddrinfo(host, port, family, type, proto, flags):\n               ~~~~~~~~~~~~~~~~~~~^^^^^^^^^^^^^^^^^^^^^^^^^^^^^^^^^^^^^^^^\n', 'socket.gaierror: [Errno 11001] getaddrinfo failed\n', '\nThe above exception was the direct cause of the following exception:\n\n', 'Traceback (most recent call last):\n', '  File "c:\\Users\\Parikh Agri Laptop\\OneDrive\\Code\\m.Stock Interface\\.venv\\Lib\\site-packages\\urllib3\\connectionpool.py", line 787, in urlopen\n    response = self._make_request(\n        conn,\n    ...<10 lines>...\n        **response_kw,\n    )\n', '  File "c:\\Users\\Parikh Agri Laptop\\OneDrive\\Code\\m.Stock Interface\\.venv\\Lib\\site-packages\\urllib3\\connectionpool.py", line 488, in _make_request\n    raise new_e\n', '  File "c:\\Users\\Parikh Agri Laptop\\OneDrive\\Code\\m.Stock Interface\\.venv\\Lib\\site-packages\\urllib3\\connectionpool.py", line 464, in _make_request\n    self._validate_conn(conn)\n    ~~~~~~~~~~~~~~~~~~~^^^^^^\n', '  File "c:\\Users\\Parikh Agri Laptop\\OneDrive\\Code\\m.Stock Interface\\.venv\\Lib\\site-packages\\urllib3\\connectionpool.py", line 1093, in _validate_conn\n    conn.connect()\n    ~~~~~~~~~~~~^^\n', '  File "c:\\Users\\Parikh Agri Laptop\\OneDrive\\Code\\m.Stock Interface\\.venv\\Lib\\site-packages\\urllib3\\connection.py", line 753, in connect\n    self.sock = sock = self._new_conn()\n                       ~~~~~~~~~~~~~~^^\n', '  File "c:\\Users\\Parikh Agri Laptop\\OneDrive\\Code\\m.Stock Interface\\.venv\\Lib\\site-packages\\urllib3\\connection.py", line 205, in _new_conn\n    raise NameResolutionError(self.host, self, e) from e\n', "urllib3.exceptions.NameResolutionError: <urllib3.connection.HTTPSConnection object at 0x000002B9FDA77D90>: Failed to resolve 'api.mstock.trade' ([Errno 11001] getaddrinfo failed)\n", '\nThe above exception was the direct cause of the following exception:\n\n', 'Traceback (most recent call last):\n', '  File "c:\\Users\\Parikh Agri Laptop\\OneDrive\\Code\\m.Stock Interface\\.venv\\Lib\\site-packages\\requests\\adapters.py", line 644, in send\n    resp = conn.urlopen(\n        method=request.method,\n    ...<9 lines>...\n        chunked=chunked,\n    )\n', '  File "c:\\Users\\Parikh Agri Laptop\\OneDrive\\Code\\m.Stock Interface\\.venv\\Lib\\site-packages\\urllib3\\connectionpool.py", line 841, in urlopen\n    retries = retries.increment(\n        method, url, error=new_e, _pool=self, _stacktrace=sys.exc_info()[2]\n    )\n', '  File "c:\\Users\\Parikh Agri Laptop\\OneDrive\\Code\\m.Stock Interface\\.venv\\Lib\\site-packages\\urllib3\\util\\retry.py", line 519, in increment\n    raise MaxRetryError(_pool, url, reason) from reason  # type: ignore[arg-type]\n    ^^^^^^^^^^^^^^^^^^^^^^^^^^^^^^^^^^^^^^^^^^^^^^^^^^^\n', 'urllib3.exceptions.MaxRetryError: HTTPSConnectionPool(host=\'api.mstock.trade\', port=443): Max retries exceeded with url: /openapi/typea/instruments/quote/ltp?i=NSE%3ASBIN (Caused by NameResolutionError("<urllib3.connection.HTTPSConnection object at 0x000002B9FDA77D90>: Failed to resolve \'api.mstock.trade\' ([Errno 11001] getaddrinfo failed)"))\n', '\nDuring handling of the above exception, another exception occurred:\n\n', 'Traceback (most recent call last):\n', '  File "c:\\Users\\Parikh Agri Laptop\\OneDrive\\Code\\m.Stock Interface\\.venv\\Lib\\site-packages\\tradingapi_a\\mconnect.py", line 307, in get_ltp\n    get_ltp_data=self._get(\n        route="market_ltp",\n        url_args=None,\n        params=ltp_details\n    )\n', '  File "c:\\Users\\Parikh Agri Laptop\\OneDrive\\Code\\m.Stock Interface\\.venv\\Lib\\site-packages\\tradingapi_a\\mconnect.py", line 477, in _get\n    return self._request(route, "GET", url_args=url_args,content_type=content_type, params=params, is_json=is_json)\n           ~~~~~~~~~~~~~^^^^^^^^^^^^^^^^^^^^^^^^^^^^^^^^^^^^^^^^^^^^^^^^^^^^^^^^^^^^^^^^^^^^^^^^^^^^^^^^^^^^^^^^^^^\n', '  File "c:\\Users\\Parikh Agri Laptop\\OneDrive\\Code\\m.Stock Interface\\.venv\\Lib\\site-packages\\tradingapi_a\\mconnect.py", line 536, in _request\n    raise e\n', '  File "c:\\Users\\Parikh Agri Laptop\\OneDrive\\Code\\m.Stock Interface\\.venv\\Lib\\site-packages\\tradingapi_a\\mconnect.py", line 526, in _request\n    response_data = self.request_session.request(method,\n                                url,\n    ...<5 lines>...\n                                allow_redirects=True,\n                                timeout=self.timeout)\n', '  File "c:\\Users\\Parikh Agri Laptop\\OneDrive\\Code\\m.Stock Interface\\.venv\\Lib\\site-packages\\requests\\sessions.py", line 589, in request\n    resp = self.send(prep, **send_kwargs)\n', '  File "c:\\Users\\Parikh Agri Laptop\\OneDrive\\Code\\m.Stock Interface\\.venv\\Lib\\site-packages\\requests\\sessions.py", line 703, in send\n    r = adapter.send(request, **kwargs)\n', '  File "c:\\Users\\Parikh Agri Laptop\\OneDrive\\Code\\m.Stock Interface\\.venv\\Lib\\site-packages\\requests\\adapters.py", line 677, in send\n    raise ConnectionError(e, request=request)\n', 'requests.exceptions.ConnectionError: HTTPSConnectionPool(host=\'api.mstock.trade\', port=443): Max retries exceeded with url: /openapi/typea/instruments/quote/ltp?i=NSE%3ASBIN (Caused by NameResolutionError("<urllib3.connection.HTTPSConnection object at 0x000002B9FDA77D90>: Failed to resolve \'api.mstock.trade\' ([Errno 11001] getaddrinfo failed)"))\n']
